Workbook

Sheet TABLA DE FORMULAS
A1: Datos Personales
A2: Nombre del paciente | B2: Bunader, José Alberto
A3: Edad | B3: 61
A4: Fecha de nacimiento | B4: 23628
A5: Nivel educativo alcanzado | B5: Terciario
A6: Lateralidad | B6: Diestro
A7: Fecha de evaluación | B7: 46265
A8: Asiste acompañado con | B8: No
A9: Derivado por | B9: No | D9: No completar
A10: Riesgo de evolución | B10: No
E11: Deterioro significativo | G11: Puntajes bajos | H11: Puntajes promedio | J11: Puntajes superiores
A12: Área | B12: Prueba | C12: PB | D12: Z | E12: < - 3 | F12: - 3 a -2 | G12: -2 a -1 | H12: -1 a 0 | I12: 0 a +1 | J12: +1 a +2 | K12: +2 a +3 | L12: > +3
A13: Screening cognitivo y psiquiátrico | B13: MMSE | C13: 30/30
B14: Orientación temporal | C14: Si
B15: Orientación espacial | C15: Si
B16: TRO | C16: 9,5/10
B17: AVD | C17: 8 | D17: =IF(C17="","",IF(C17>=8,"Autónomo",IF(C17>=6,"Dependencia leve",IF(C17>=4,"Dependencia moderada",IF(C17>=2,"Dependencia severa","Dependencia total"))))) -> Autónomo
B18: KPDS-10 | C18: =B63 -> 15 | D18: =IF(C18="","",IF(C18>=30,"Malestar severo",IF(C18>=25,"Malestar moderado","Normal"))) -> Normal
A19: Atención y funciones ejecutivas | B19: DD | C19: 7 | D19: =(C19-Q32)/R32 -> 0.44827586 | E19: =IF(ISNUMBER($D19),IF($D19<-3,"X",""),"") | F19: =IF(ISNUMBER($D19),IF(AND($D19>=-3,$D19<-2),"X",""),"") | G19: =IF(ISNUMBER($D19),IF(AND($D19>=-2,$D19<-1),"X",""),"") | H19: =IF(ISNUMBER($D19),IF(AND($D19>=-1,$D19<0),"X",""),"") | I19: =IF(ISNUMBER($D19),IF(AND($D19>=0,$D19<1),"X",""),"") -> X | J19: =IF(ISNUMBER($D19),IF(AND($D19>=1,$D19<2),"X",""),"") | K19: =IF(ISNUMBER($D19),IF(AND($D19>=2,$D19<3),"X",""),"") | L19: =IF(ISNUMBER($D19),IF($D19>=3,"X",""),"")
B20: DI | C20: 4 | D20: =(C20-Q33)/R33 -> -0.3525641 | E20: =IF(ISNUMBER($D20),IF($D20<-3,"X",""),"") | F20: =IF(ISNUMBER($D20),IF(AND($D20>=-3,$D20<-2),"X",""),"") | G20: =IF(ISNUMBER($D20),IF(AND($D20>=-2,$D20<-1),"X",""),"") | H20: =IF(ISNUMBER($D20),IF(AND($D20>=-1,$D20<0),"X",""),"") -> X | I20: =IF(ISNUMBER($D20),IF(AND($D20>=0,$D20<1),"X",""),"") | J20: =IF(ISNUMBER($D20),IF(AND($D20>=1,$D20<2),"X",""),"") | K20: =IF(ISNUMBER($D20),IF(AND($D20>=2,$D20<3),"X",""),"") | L20: =IF(ISNUMBER($D20),IF($D20>=3,"X",""),"")
B21: TMT A | C21: 38 | D21: =((C21-Q34)/R34)*-1 -> -0.18487395 | E21: =IF(ISNUMBER($D21),IF($D21<-3,"X",""),"") | F21: =IF(ISNUMBER($D21),IF(AND($D21>=-3,$D21<-2),"X",""),"") | G21: =IF(ISNUMBER($D21),IF(AND($D21>=-2,$D21<-1),"X",""),"") | H21: =IF(ISNUMBER($D21),IF(AND($D21>=-1,$D21<0),"X",""),"") -> X | I21: =IF(ISNUMBER($D21),IF(AND($D21>=0,$D21<1),"X",""),"") | J21: =IF(ISNUMBER($D21),IF(AND($D21>=1,$D21<2),"X",""),"") | K21: =IF(ISNUMBER($D21),IF(AND($D21>=2,$D21<3),"X",""),"") | L21: =IF(ISNUMBER($D21),IF($D21>=3,"X",""),"")
B22: TMT B | C22: 42 | D22: =((C22-Q35)/R35)*-1 -> 1.0181818 | E22: =IF(ISNUMBER($D22),IF($D22<-3,"X",""),"") | F22: =IF(ISNUMBER($D22),IF(AND($D22>=-3,$D22<-2),"X",""),"") | G22: =IF(ISNUMBER($D22),IF(AND($D22>=-2,$D22<-1),"X",""),"") | H22: =IF(ISNUMBER($D22),IF(AND($D22>=-1,$D22<0),"X",""),"") | I22: =IF(ISNUMBER($D22),IF(AND($D22>=0,$D22<1),"X",""),"") | J22: =IF(ISNUMBER($D22),IF(AND($D22>=1,$D22<2),"X",""),"") -> X | K22: =IF(ISNUMBER($D22),IF(AND($D22>=2,$D22<3),"X",""),"") | L22: =IF(ISNUMBER($D22),IF($D22>=3,"X",""),"")
B23: FF | C23: 24 | D23: =(C23-Q36)/R36 -> 2.3125 | E23: =IF(ISNUMBER($D23),IF($D23<-3,"X",""),"") | F23: =IF(ISNUMBER($D23),IF(AND($D23>=-3,$D23<-2),"X",""),"") | G23: =IF(ISNUMBER($D23),IF(AND($D23>=-2,$D23<-1),"X",""),"") | H23: =IF(ISNUMBER($D23),IF(AND($D23>=-1,$D23<0),"X",""),"") | I23: =IF(ISNUMBER($D23),IF(AND($D23>=0,$D23<1),"X",""),"") | J23: =IF(ISNUMBER($D23),IF(AND($D23>=1,$D23<2),"X",""),"") | K23: =IF(ISNUMBER($D23),IF(AND($D23>=2,$D23<3),"X",""),"") -> X | L23: =IF(ISNUMBER($D23),IF($D23>=3,"X",""),"")
B24: IFS Total | C24: 26,5/30
B25: IFS Índice MT | C25: 7/10
B26: IFS SM | C26: 3 normal
B27: IFS IC | C27: 3 normal
B28: IFS CIM | C28: 3 normal
B29: IFS DA | C29: 4 normal | P29: No completar
B30: IFS MA | C30: 2 normal
B31: IFS MTV | C31: 3 normal | Q31: Media | R31: Desvio
B32: IFS R | C32: 2,5 normal | Q32: =VLOOKUP(B3,PRUEBAS!$I$3:$K$89,2,FALSE) -> 6.35 | R32: =VLOOKUP(B3,PRUEBAS!$I$3:$K$89,3,FALSE) -> 1.45
B33: IFS CIV | C33: 6 normal | Q33: =VLOOKUP(B3,PRUEBAS!$M$3:$O$89,2,FALSE) -> 4.55 | R33: =VLOOKUP(B3,PRUEBAS!$M$3:$O$89,3,FALSE) -> 1.56
A34: Memoria episódica | B34: BEM – MS AS1 | C34: 5 | Q34: =VLOOKUP(B3,PRUEBAS!$A$3:$C$89,2,FALSE) -> 35.8 | R34: =VLOOKUP(B3,PRUEBAS!$A$3:$C$89,3,FALSE) -> 11.9
B35: BEM – MS AS2 | C35: 8 | Q35: =VLOOKUP(B3,PRUEBAS!$E$3:$G$89,2,FALSE) -> 81.2 | R35: =VLOOKUP(B3,PRUEBAS!$E$3:$G$89,3,FALSE) -> 38.5
B36: BEM – MS AS3 | C36: 10 | Q36: =VLOOKUP(B3,FLUENCIAS!$K$2:$N$88,(MATCH(B5,FLUENCIAS!$L$2:$N$2,0))+1,0) -> 16.6 | R36: =VLOOKUP(B3,FLUENCIAS!$P$2:$S$88,(MATCH(B5,FLUENCIAS!$Q$2:$S$2,0))+1,0) -> 3.2
B37: BEM – MS AST | C37: =TRUNC(V38,2) -> 7.66 | D37: =(C37-Q37)/R37 -> -0.89944134 | E37: =IF(ISNUMBER($D37),IF($D37<-3,"X",""),"") | F37: =IF(ISNUMBER($D37),IF(AND($D37>=-3,$D37<-2),"X",""),"") | G37: =IF(ISNUMBER($D37),IF(AND($D37>=-2,$D37<-1),"X",""),"") | H37: =IF(ISNUMBER($D37),IF(AND($D37>=-1,$D37<0),"X",""),"") -> X | I37: =IF(ISNUMBER($D37),IF(AND($D37>=0,$D37<1),"X",""),"") | J37: =IF(ISNUMBER($D37),IF(AND($D37>=1,$D37<2),"X",""),"") | K37: =IF(ISNUMBER($D37),IF(AND($D37>=2,$D37<3),"X",""),"") | L37: =IF(ISNUMBER($D37),IF($D37>=3,"X",""),"") | Q37: =VLOOKUP(B3,PRUEBAS!$AC$3:$AE$89,2,FALSE) -> 9.27 | R37: =VLOOKUP(B3,PRUEBAS!$AC$3:$AE$89,3,FALSE) -> 1.79 | T37: MS - Signoret | V37: BEM – MS AST
B38: BEM – MS RSE | C38: 8 | D38: =(C38-Q38)/R38 -> -0.12568306 | E38: =IF(ISNUMBER($D38),IF($D38<-3,"X",""),"") | F38: =IF(ISNUMBER($D38),IF(AND($D38>=-3,$D38<-2),"X",""),"") | G38: =IF(ISNUMBER($D38),IF(AND($D38>=-2,$D38<-1),"X",""),"") | H38: =IF(ISNUMBER($D38),IF(AND($D38>=-1,$D38<0),"X",""),"") -> X | I38: =IF(ISNUMBER($D38),IF(AND($D38>=0,$D38<1),"X",""),"") | J38: =IF(ISNUMBER($D38),IF(AND($D38>=1,$D38<2),"X",""),"") | K38: =IF(ISNUMBER($D38),IF(AND($D38>=2,$D38<3),"X",""),"") | L38: =IF(ISNUMBER($D38),IF($D38>=3,"X",""),"") | Q38: =VLOOKUP(B3,PRUEBAS!$AG$3:$AI$89,2,FALSE) -> 8.23 | R38: =VLOOKUP(B3,PRUEBAS!$AG$3:$AI$89,3,FALSE) -> 1.83 | T38: AS1 | U38: =C34 -> 5 | V38: =(U38+U39+U40)/3 -> 7.6666667
B39: BEM – MS Sem | C39: 8 | D39: =(C39-Q39)/R39 -> -3.1067961 | E39: =IF(ISNUMBER($D39),IF($D39<-3,"X",""),"") -> X | F39: =IF(ISNUMBER($D39),IF(AND($D39>=-3,$D39<-2),"X",""),"") | G39: =IF(ISNUMBER($D39),IF(AND($D39>=-2,$D39<-1),"X",""),"") | H39: =IF(ISNUMBER($D39),IF(AND($D39>=-1,$D39<0),"X",""),"") | I39: =IF(ISNUMBER($D39),IF(AND($D39>=0,$D39<1),"X",""),"") | J39: =IF(ISNUMBER($D39),IF(AND($D39>=1,$D39<2),"X",""),"") | K39: =IF(ISNUMBER($D39),IF(AND($D39>=2,$D39<3),"X",""),"") | L39: =IF(ISNUMBER($D39),IF($D39>=3,"X",""),"") | Q39: =VLOOKUP(B3,PRUEBAS!$AK$3:$AM$89,2,FALSE) -> 11.2 | R39: =VLOOKUP(B3,PRUEBAS!$AK$3:$AM$89,3,FALSE) -> 1.03 | T39: AS2 | U39: =C35 -> 8
B40: BEM – MS Rec | C40: 12 | D40: =(C40-Q40)/R40 -> 0.56603774 | E40: =IF(ISNUMBER($D40),IF($D40<-3,"X",""),"") | F40: =IF(ISNUMBER($D40),IF(AND($D40>=-3,$D40<-2),"X",""),"") | G40: =IF(ISNUMBER($D40),IF(AND($D40>=-2,$D40<-1),"X",""),"") | H40: =IF(ISNUMBER($D40),IF(AND($D40>=-1,$D40<0),"X",""),"") | I40: =IF(ISNUMBER($D40),IF(AND($D40>=0,$D40<1),"X",""),"") -> X | J40: =IF(ISNUMBER($D40),IF(AND($D40>=1,$D40<2),"X",""),"") | K40: =IF(ISNUMBER($D40),IF(AND($D40>=2,$D40<3),"X",""),"") | L40: =IF(ISNUMBER($D40),IF($D40>=3,"X",""),"") | Q40: =VLOOKUP(B3,PRUEBAS!$AO$3:$AQ$89,2,FALSE) -> 11.7 | R40: =VLOOKUP(B3,PRUEBAS!$AO$3:$AQ$89,3,FALSE) -> 0.53 | T40: AS3 | U40: =C36 -> 10
...

Sheet Stroop
C2: Puntaje | E2: PC Estimado | F2: Interferencia | H2: P | I2: C | J2: PC | K2: Interferencia | L2: T
B3: P | E3: =(C3*C4)/(C3+C4) -> #DIV/0! | F3: =C5-E3 -> #DIV/0! | H3: 168 | I3: 125 | J3: 75 | K3: 30 | L3: 80
B4: C | H4: 164 | I4: 122 | J4: 73 | K4: 28 | L4: 78
B5: PC | H5: 160 | I5: 119 | J5: 71 | K5: 26 | L5: 76
H6: 156 | I6: 116 | J6: 69 | K6: 24 | L6: 74
H7: 152 | I7: 113 | J7: 67 | K7: 22 | L7: 72
H8: 148 | I8: 110 | J8: 65 | K8: 20 | L8: 70
B9: Ajuste por Edad | H9: 144 | I9: 107 | J9: 63 | K9: 18 | L9: 68
C10: P | D10: C | E10: PC | H10: 140 | I10: 104 | J10: 61 | K10: 16 | L10: 66
B11: 16-44 | C11: =C3 -> 0 | D11: =C4 -> 0 | E11: =C5 -> 0 | H11: 136 | I11: 101 | J11: 59 | K11: 14 | L11: 64
B12: 45-64 | C12: =C3+8 -> 8 | D12: =C4+4 -> 4 | E12: =C5+5 -> 5 | H12: 132 | I12: 98 | J12: 57 | K12: 12 | L12: 62
B13: 65 | C13: =C3+14 -> 14 | D13: =C4+11 -> 11 | E13: =C5+15 -> 15 | H13: 128 | I13: 95 | J13: 55 | K13: 10 | L13: 60
H14: 124 | I14: 92 | J14: 53 | K14: 8 | L14: 58
H15: 120 | I15: 89 | J15: 51 | K15: 6 | L15: 56
H16: 116 | I16: 86 | J16: 49 | K16: 4 | L16: 54
H17: 112 | I17: 83 | J17: 47 | K17: 2 | L17: 52
H18: 108 | I18: 80 | J18: 45 | K18: 0 | L18: 50
H19: 104 | I19: 77 | J19: 43 | K19: -2 | L19: 48
H20: 100 | I20: 74 | J20: 41 | K20: -4 | L20: 46
H21: 96 | I21: 71 | J21: 39 | K21: -6 | L21: 44
H22: 92 | I22: 68 | J22: 37 | K22: -8 | L22: 42
H23: 88 | I23: 65 | J23: 35 | K23: -10 | L23: 40
H24: 84 | I24: 62 | J24: 33 | K24: -12 | L24: 38
H25: 80 | I25: 59 | J25: 31 | K25: -14 | L25: 36
... H33: 48 | I33: 35 | J33: 15 | K33: -30 | L33: 20

Sheet MMSE
B2: MMSE
B3: (baremos Argentina)
B4: Años educación | C4: < 45 años | D4: 46 a 55 años | E4: 56 a 65 años | F4: 66 a 75 años | G4: > 75 años
B5: < 5 | D5: 27,5 (1,5) | E5: 26,6 (1,2) | F5: 26,7 (2,4)
E6: Pje de corte: 24 | F6: Pje de corte: 24 | G6: Pje de corte: 22
B7: 5 a 7 | C7: 28,8 (1,0) | D7: 29,2 (0,6) | E7: 28,6 (1,1) | F7: 28,4 (1,2) | G7: 27,6 (1,8)
C8: Pje de corte: 27 | D8: Pje de corte: 27 | E8: Pje de corte: 26 | F8: Pje de corte: 26 | G8: Pje de corte: 25
B9: 8 a 12 | C9: 29,1 (0,8) | D9: 29,2 (0,8) | E9: 28,8 (0,9) | F9: 28,8 (0,9) | G9: 28,1 (1,3)
C10: Pje de corte: 27 | D10: Pje de corte: 27 | E10: Pje de corte: 27 | F10: Pje de corte: 27 | G10: Pje de corte: 25
B11: > 12 | C11: 29,2 (0,7) | D11: 29,2 (0,8) | E11: 28,0 (0,9) | F11: 28,7 (0,9) | G11: 28,6 (0,9)
C12: Pje de corte: 27 | D12: Pje de corte: 27 | E12: Pje de corte: 27 | F12: Pje de corte: 27 | G12: Pje de corte: 26

Sheet Puntajes Equivalentes
A1: DESCRIPTOR | B1: PERCENTIL | C1: PUNTAJE Z | D1: PUNTAJE T | E1: PUNTAJE ESCALAR | F1: PUNTAJE CI | G1: DESCRIPTOR
A2: PUNTAJE SUPERIOR | B2: > 99.9 | C2: 4 | D2: 90 | F2: 150/155 | G2: PUNTAJE SUPERIOR
B3: 99.9 | C3: 3 | D3: 80 | E3: 19 | F3: 145
B4: 99 | C4: 2.5 | D4: 75 | E4: 17/18 | F4: 135/140
A5: PUNTAJE ALTO | B5: 98 | C5: 2 | D5: 70 | E5: 16 | F5: 130 | G5: PUNTAJE ALTO
B6: 97 | C6: 1.9 | D6: 69
B7: 96 | C7: 1.7 | D7: 67 | E7: 15 | F7: 125
B8: 95 | C8: 1.6 | D8: 66
B9: 93 | C9: 1.5 | D9: 65
B10: 92 | C10: 1.4 | D10: 64
B11: 90 | C11: 1.3 | D11: 63 | E11: 14 | F11: 120
B12: 88 | C12: 1.2 | D12: 62
B13: 86 | C13: 1.1 | D13: 61
A14: PUNTAJE PROMEDIO | B14: 84 | C14: 1 | D14: 60 | E14: 13 | F14: 115 | G14: PUNTAJE PROMEDIO
B15: 82 | C15: 0.9 | D15: 59
B16: 79 | C16: 0.8 | D16: 58
B17: 76 | C17: 0.7 | D17: 57 | E17: 12 | F17: 110
B18: 73 | C18: 0.6 | D18: 56
B19: 69 | C19: 0.5 | D19: 55
B20: 66 | C20: 0.4 | D20: 54
B21: 62 | C21: 0.3 | D21: 53 | E21: 11 | F21: 105
B22: 58 | C22: 0.2 | D22: 52
B23: 54 | C23: 0.1 | D23: 51
B24: 50 | C24: 0 | D24: 50 | E24: 10 | F24: 100
B25: 46 | C25: -0.1 | D25: 49
B26: 42 | C26: -0.2 | D26: 48
B27: 38 | C27: -0.3 | D27: 47 | E27: 9 | F27: 95
B28: 34 | C28: -0.4 | D28: 46
B29: 31 | C29: -0.5 | D29: 45
B30: 27 | C30: -0.6 | D30: 44
B31: 24 | C31: -0.7 | D31: 43 | E31: 8 | F31: 90
B32: 21 | C32: -0.8 | D32: 42
B33: 18 | C33: -0.9 | D33: 43
B34: 16 | C34: -1 | D34: 40 | E34: 7 | F34: 85
A35: PUNTAJE BAJO | B35: 14 | C35: -1.1 | D35: 39 | G35: PUNTAJE BAJO
B36: 12 | C36: -1.2 | D36: 38
B37: 10 | C37: -1.3 | D37: 37 | E37: 6 | F37: 80
B38: 8 | C38: -1.4 | D38: 36
B39: 7 | C39: -1.5 | D39: 35
B40: 5 | C40: -1.6 | D40: 34
...

Sheet PRUEBAS
A2: TMT A | E2: TMT B | I2: DIGITOS DIRECTOS | M2: DÍGITOS INVERSOS | Q2: BOSTON ABREVIADO | U2: MEMORIA LOGICA INM | Y2: MEMORIA LOGICA DIF | AC2: MEMORIA SERIADA AS | AG2: MEMORIA SERIADA RS | AK2: MEMORIA SERIADA SEM | AO2: MEMORIA SERIADA REC | AS2: MEMORIA SERIADA PROM
A3: EDAD | B3: Media | C3: Desvío | E3: EDAD | F3: Media | G3: Desvío | I3: EDAD | J3: Media | K3: Desvío | M3: EDAD | N3: Media | O3: Desvío | Q3: EDAD | R3: Media | S3: Desvío | U3: EDAD | V3: Media | W3: Desvío | Y3: EDAD | Z3: Media | AA3: Desvío | AC3: EDAD | AD3: Media | AE3: Desvío | AG3: EDAD | AH3: Media | AI3: Desvío | AK3: EDAD | AL3: Media | AM3: Desvío | AO3: EDAD | AP3: Media | AQ3: Desvío | AS3: EDAD | AT3: Media | AU3: Desvío
A4: 15 | B4: 25.7 | C4: 8.8 | E4: 15 | F4: 49.8 | G4: 15.2 | I4: 15 | J4: 6.72 | K4: 1.32 | M4: 15 | N4: 4.88 | O4: 1.44 | Q4: 15 | R4: 11 | S4: 1.16 | U4: 15 | V4: 9.19 | W4: 2.12 | Y4: 15 | Z4: 9.22 | AA4: 2.07 | AC4: 15 | AD4: 9.92 | AE4: 1.69 | AG4: 15 | AH4: 8.97 | AI4: 1.87 | AK4: 15 | AL4: 11 | AM4: 1.62 | AO4: 15 | AP4: 11.85 | AQ4: 0.47 | AS4: 15 | AT4: 11.42 | AU4: 0.94
A5: 16 | B5: 25.7 | C5: 8.8 | E5: 16 | F5: 49.8 | G5: 15.2 | I5: 16 | J5: 6.72 | K5: 1.32 | M5: 16 | N5: 4.88 | O5: 1.44 | Q5: 16 | R5: 11 | S5: 1.16 | U5: 16 | V5: 9.19 | W5: 2.12 | Y5: 16 | Z5: 9.22 | AA5: 2.07 | AC5: 16 | AD5: 9.92 | AE5: 1.69 | AG5: 16 | AH5: 8.97 | AI5: 1.87 | AK5: 16 | AL5: 11 | AM5: 1.62 | AO5: 16 | AP5: 11.85 | AQ5: 0.47 | AS5: 16 | AT5: 11.42 | AU5: 0.94
A6: 17 | B6: 25.7 | C6: 8.8 | E6: 17 | F6: 49.8 | G6: 15.2 | I6: 17 | J6: 6.72 | K6: 1.32 | M6: 17 | N6: 4.88 | O6: 1.44 | Q6: 17 | R6: 11 | S6: 1.16 | U6: 17 | V6: 9.19 | W6: 2.12 | Y6: 17 | Z6: 9.22 | AA6: 2.07 | AC6: 17 | AD6: 9.92 | AE6: 1.69 | AG6: 17 | AH6: 8.97 | AI6: 1.87 | AK6: 17 | AL6: 11 | AM6: 1.62 | AO6: 17 | AP6: 11.85 | AQ6: 0.47 | AS6: 17 | AT6: 11.42 | AU6: 0.94
A7: 18 | B7: 25.7 | C7: 8.8 | E7: 18 | F7: 49.8 | G7: 15.2 | I7: 18 | J7: 6.66 | K7: 1.34 | M7: 18 | N7: 5.04 | O7: 1.46 | Q7: 18 | R7: 11 | S7: 1.16 | U7: 18 | V7: 9.19 | W7: 2.12 | Y7: 18 | Z7: 9.22 | AA7: 2.07 | AC7: 18 | AD7: 9.92 | AE7: 1.69 | AG7: 18 | AH7: 8.97 | AI7: 1.87 | AK7: 18 | AL7: 11 | AM7: 1.62 | AO7: 18 | AP7: 11.85 | AQ7: 0.47 | AS7: 18 | AT7: 11.42 | AU7: 0.94
A8: 19 | B8: 25.7 | C8: 8.8 | E8: 19 | F8: 49.8 | G8: 15.2 | I8: 19 | J8: 6.66 | K8: 1.34 | M8: 19 | N8: 5.04 | O8: 1.46 | Q8: 19 | R8: 11 | S8: 1.16 | U8: 19 | V8: 9.19 | W8: 2.12 | Y8: 19 | Z8: 9.22 | AA8: 2.07 | AC8: 19 | AD8: 9.92 | AE8: 1.69 | AG8: 19 | AH8: 8.97 | AI8: 1.87 | AK8: 19 | AL8: 11 | AM8: 1.62 | AO8: 19 | AP8: 11.85 | AQ8: 0.47 | AS8: 19 | AT8: 11.42 | AU8: 0.94
A9: 20 | B9: 27.4 | C9: 9.6 | E9: 20 | F9: 58.7 | G9: 15.9 | I9: 20 | J9: 6.8 | K9: 1.27 | M9: 20 | N9: 5.1 | O9: 1.51 | Q9: 20 | R9: 11 | S9: 1.16 | U9: 20 | V9: 9.19 | W9: 2.12 | Y9: 20 | Z9: 9.22 | AA9: 2.07 | AC9: 20 | AD9: 9.92 | AE9: 1.69 | AG9: 20 | AH9: 8.97 | AI9: 1.87 | AK9: 20 | AL9: 11 | AM9: 1.62 | AO9: 20 | AP9: 11.85 | AQ9: 0.47 | AS9: 20 | AT9: 11.42 | AU9: 0.94
A10: 21 | B10: 27.4 | C10: 9.6 | E10: 21 | F10: 58.7 | G10: 15.9 | I10: 21 | J10: 6.8 | K10: 1.27 | M10: 21 | N10: 5.1 | O10: 1.51 | Q10: 21 | R10: 11 | S10: 1.16 | U10: 21 | V10: 9.19 | W10: 2.12 | Y10: 21 | Z10: 9.22 | AA10: 2.07 | AC10: 21 | AD10: 9.92 | AE10: 1.69 | AG10: 21 | AH10: 8.97 | AI10: 1.87 | AK10: 21 | AL10: 11 | AM10: 1.62 | AO10: 21 | AP10: 11.85 | AQ10: 0.47 | AS10: 21 | AT10: 11.42 | AU10: 0.94
A11: 22 | B11: 27.4 | C11: 9.6 | E11: 22 | F11: 58.7 | G11: 15.9 | I11: 22 | J11: 6.8 | K11: 1.27 | M11: 22 | N11: 5.1 | O11: 1.51 | Q11: 22 | R11: 11 | S11: 1.16 | U11: 22 | V11: 9.19 | W11: 2.12 | Y11: 22 | Z11: 9.22 | AA11: 2.07 | AC11: 22 | AD11: 9.92 | AE11: 1.69 | AG11: 22 | AH11: 8.97 | AI11: 1.87 | AK11: 22 | AL11: 11 | AM11: 1.62 | AO11: 22 | AP11: 11.85 | AQ11: 0.47 | AS11: 22 | AT11: 11.42 | AU11: 0.94
A12: 23 | B12: 27.4 | C12: 9.6 | E12: 23 | F12: 58.7 | G12: 15.9 | I12: 23 | J12: 6.8 | K12: 1.27 | M12: 23 | N12: 5.1 | O12: 1.51 | Q12: 23 | R12: 11 | S12: 1.16 | U12: 23 | V12: 9.19 | W12: 2.12 | Y12: 23 | Z12: 9.22 | AA12: 2.07 | AC12: 23 | AD12: 9.92 | AE12: 1.69 | AG12: 23 | AH12: 8.97 | AI12: 1.87 | AK12: 23 | AL12: 11 | AM12: 1.62 | AO12: 23 | AP12: 11.85 | AQ12: 0.47 | AS12: 23 | AT12: 11.42 | AU12: 0.94
A13: 24 | B13: 27.4 | C13: 9.6 | E13: 24 | F13: 58.7 | G13: 15.9 | I13: 24 | J13: 6.8 | K13: 1.27 | M13: 24 | N13: 5.1 | O13: 1.51 | Q13: 24 | R13: 11 | S13: 1.16 | U13: 24 | V13: 9.19 | W13: 2.12 | Y13: 24 | Z13: 9.22 | AA13: 2.07 | AC13: 24 | AD13: 9.92 | AE13: 1.69 | AG13: 24 | AH13: 8.97 | AI13: 1.87 | AK13: 24 | AL13: 11 | AM13: 1.62 | AO13: 24 | AP13: 11.85 | AQ13: 0.47 | AS13: 24 | AT13: 11.42 | AU13: 0.94
A14: 25 | B14: 27.4 | C14: 9.6 | E14: 25 | F14: 58.7 | G14: 15.9 | I14: 25 | J14: 6.68 | K14: 1.35 | M14: 25 | N14: 5.04 | O14: 1.63 | Q14: 25 | R14: 11 | S14: 1.16 | U14: 25 | V14: 9.19 | W14: 2.12 | Y14: 25 | Z14: 9.22 | AA14: 2.07 | AC14: 25 | AD14: 9.92 | AE14: 1.69 | AG14: 25 | AH14: 8.97 | AI14: 1.87 | AK14: 25 | AL14: 11 | AM14: 1.62 | AO14: 25 | AP14: 11.85 | AQ14: 0.47 | AS14: 25 | AT14: 11.42 | AU14: 0.94
A15: 26 | B15: 27.4 | C15: 9.6 | E15: 26 | F15: 58.7 | G15: 15.9 | I15: 26 | J15: 6.68 | K15: 1.35 | M15: 26 | N15: 5.04 | O15: 1.63 | Q15: 26 | R15: 11 | S15: 1.16 | U15: 26 | V15: 9.19 | W15: 2.12 | Y15: 26 | Z15: 9.22 | AA15: 2.07 | AC15: 26 | AD15: 9.92 | AE15: 1.69 | AG15: 26 | AH15: 8.97 | AI15: 1.87 | AK15: 26 | AL15: 11 | AM15: 1.62 | AO15: 26 | AP15: 11.85 | AQ15: 0.47 | AS15: 26 | AT15: 11.42 | AU15: 0.94
... A35: 46 | B35: 30.7 | C35: 8.8 | E35: 46 | F35: 64.4 | G35: 18.3 | I35: 46 | J35: 6.57 | K35: 1.38 | M35: 46 | N35: 4.79 | O35: 1.42 | Q35: 46 | R35: 11 | S35: 1.16 | U35: 46 | V35: 9.07 | W35: 1.83 | Y35: 46 | Z35: 8.97 | AA35: 1.9 | AC35: 46 | AD35: 9.88 | AE35: 1.04 | AG35: 46 | AH35: 9.16 | AI35: 1.67 | AK35: 46 | AL35: 11.16 | AM35: 1.39 | AO35: 46 | AP35: 11.91 | AQ35: 0.29 | AS35: 46 | AT35: 11.53 | AU35: 0.75
A36: =A35+1 -> 47 | B36: 30.7 | C36: 8.8 | E36: =E35+1 -> 47 | F36: 64.4 | G36: 18.3 | I36: =I35+1 -> 47 | J36: 6.57 | K36: 1.38 | M36: =M35+1 -> 47 | N36: 4.79 | O36: 1.42 | Q36: =Q35+1 -> 47 | R36: 11 | S36: 1.16 | U36: =U35+1 -> 47 | V36: 9.07 | W36: 1.83 | Y36: =Y35+1 -> 47 | Z36: 8.97 | AA36: 1.9 | AC36: =AC35+1 -> 47 | AD36: 9.88 | AE36: 1.04 | AG36: =AG35+1 -> 47 | AH36: 9.16 | AI36: 1.67 | AK36: =AK35+1 -> 47 | AL36: 11.16 | AM36: 1.39 | AO36: =AO35+1 -> 47 | AP36: 11.91 | AQ36: 0.29 | AS36: =AS35+1 -> 47 | AT36: 11.53 | AU36: 0.75
A37: =A36+1 -> 48 | B37: 30.7 | C37: 8.8 | E37: =E36+1 -> 48 | F37: 64.4 | G37: 18.3 | I37: =I36+1 -> 48 | J37: 6.57 | K37: 1.38 | M37: =M36+1 -> 48 | N37: 4.79 | O37: 1.42 | Q37: =Q36+1 -> 48 | R37: 11 | S37: 1.16 | U37: =U36+1 -> 48 | V37: 9.07 | W37: 1.83 | Y37: =Y36+1 -> 48 | Z37: 8.97 | AA37: 1.9 | AC37: =AC36+1 -> 48 | AD37: 9.88 | AE37: 1.04 | AG37: =AG36+1 -> 48 | AH37: 9.16 | AI37: 1.67 | AK37: =AK36+1 -> 48 | AL37: 11.16 | AM37: 1.39 | AO37: =AO36+1 -> 48 | AP37: 11.91 | AQ37: 0.29 | AS37: =AS36+1 -> 48 | AT37: 11.53 | AU37: 0.75
A38: =A37+1 -> 49 | B38: 30.7 | C38: 8.8 | E38: =E37+1 -> 49 | F38: 64.4 | G38: 18.3 | I38: =I37+1 -> 49 | J38: 6.57 | K38: 1.38 | M38: =M37+1 -> 49 | N38: 4.79 | O38: 1.42 | Q38: =Q37+1 -> 49 | R38: 11 | S38: 1.16 | U38: =U37+1 -> 49 | V38: 9.07 | W38: 1.83 | Y38: =Y37+1 -> 49 | Z38: 8.97 | AA38: 1.9 | AC38: =AC37+1 -> 49 | AD38: 9.88 | AE38: 1.04 | AG38: =AG37+1 -> 49 | AH38: 9.16 | AI38: 1.67 | AK38: =AK37+1 -> 49 | AL38: 11.16 | AM38: 1.39 | AO38: =AO37+1 -> 49 | AP38: 11.91 | AQ38: 0.29 | AS38: =AS37+1 -> 49 | AT38: 11.53 | AU38: 0.75
A39: =A38+1 -> 50 | B39: 35.1 | C39: 10.6 | E39: =E38+1 -> 50 | F39: 77.7 | G39: 23.8 | I39: =I38+1 -> 50 | J39: 6.57 | K39: 1.38 | M39: =M38+1 -> 50 | N39: 4.79 | O39: 1.42 | Q39: =Q38+1 -> 50 | R39: 11 | S39: 1.16 | U39: =U38+1 -> 50 | V39: 9.07 | W39: 1.83 | Y39: =Y38+1 -> 50 | Z39: 8.97 | AA39: 1.9 | AC39: =AC38+1 -> 50 | AD39: 9.88 | AE39: 1.04 | AG39: =AG38+1 -> 50 | AH39: 9.16 | AI39: 1.67 | AK39: =AK38+1 -> 50 | AL39: 11.16 | AM39: 1.39 | AO39: =AO38+1 -> 50 | AP39: 11.91 | AQ39: 0.29 | AS39: =AS38+1 -> 50 | AT39: 11.53 | AU39: 0.75
A40: =A39+1 -> 51 | B40: 35.1 | C40: 10.6 | E40: =E39+1 -> 51 | F40: 77.7 | G40: 23.8 | I40: =I39+1 -> 51 | J40: 6.57 | K40: 1.38 | M40: =M39+1 -> 51 | N40: 4.79 | O40: 1.42 | Q40: =Q39+1 -> 51 | R40: 11 | S40: 1.16 | U40: =U39+1 -> 51 | V40: 9.07 | W40: 1.83 | Y40: =Y39+1 -> 51 | Z40: 8.97 | AA40: 1.9 | AC40: =AC39+1 -> 51 | AD40: 9.88 | AE40: 1.04 | AG40: =AG39+1 -> 51 | AH40: 9.16 | AI40: 1.67 | AK40: =AK39+1 -> 51 | AL40: 11.16 | AM40: 1.39 | AO40: =AO39+1 -> 51 | AP40: 11.91 | AQ40: 0.29 | AS40: =AS39+1 -> 51 | AT40: 11.53 | AU40: 0.75
A41: =A40+1 -> 52 | B41: 35.1 | C41: 10.6 | E41: =E40+1 -> 52 | F41: 77.7 | G41: 23.8 | I41: =I40+1 -> 52 | J41: 6.57 | K41: 1.38 | M41: =M40+1 -> 52 | N41: 4.79 | O41: 1.42 | Q41: =Q40+1 -> 52 | R41: 11 | S41: 1.16 | U41: =U40+1 -> 52 | V41: 9.07 | W41: 1.83 | Y41: =Y40+1 -> 52 | Z41: 8.97 | AA41: 1.9 | AC41: =AC40+1 -> 52 | AD41: 9.88 | AE41: 1.04 | AG41: =AG40+1 -> 52 | AH41: 9.16 | AI41: 1.67 | AK41: =AK40+1 -> 52 | AL41: 11.16 | AM41: 1.39 | AO41: =AO40+1 -> 52 | AP41: 11.91 | AQ41: 0.29 | AS41: =AS40+1 -> 52 | AT41: 11.53 | AU41: 0.75
A42: =A41+1 -> 53 | B42: 35.1 | C42: 10.6 | E42: =E41+1 -> 53 | F42: 77.7 | G42: 23.8 | I42: =I41+1 -> 53 | J42: 6.57 | K42: 1.38 | M42: =M41+1 -> 53 | N42: 4.79 | O42: 1.42 | Q42: =Q41+1 -> 53 | R42: 11 | S42: 1.16 | U42: =U41+1 -> 53 | V42: 9.07 | W42: 1.83 | Y42: =Y41+1 -> 53 | Z42: 8.97 | AA42: 1.9 | AC42: =AC41+1 -> 53 | AD42: 9.88 | AE42: 1.04 | AG42: =AG41+1 -> 53 | AH42: 9.16 | AI42: 1.67 | AK42: =AK41+1 -> 53 | AL42: 11.16 | AM42: 1.39 | AO42: =AO41+1 -> 53 | AP42: 11.91 | AQ42: 0.29 | AS42: =AS41+1 -> 53 | AT42: 11.53 | AU42: 0.75
A43: =A42+1 -> 54 | B43: 35.1 | C43: 10.6 | E43: =E42+1 -> 54 | F43: 77.7 | G43: 23.8 | I43: =I42+1 -> 54 | J43: 6.57 | K43: 1.38 | M43: =M42+1 -> 54 | N43: 4.79 | O43: 1.42 | Q43: =Q42+1 -> 54 | R43: 11 | S43: 1.16 | U43: =U42+1 -> 54 | V43: 9.07 | W43: 1.83 | Y43: =Y42+1 -> 54 | Z43: 8.97 | AA43: 1.9 | AC43: =AC42+1 -> 54 | AD43: 9.88 | AE43: 1.04 | AG43: =AG42+1 -> 54 | AH43: 9.16 | AI43: 1.67 | AK43: =AK42+1 -> 54 | AL43: 11.16 | AM43: 1.39 | AO43: =AO42+1 -> 54 | AP43: 11.91 | AQ43: 0.29 | AS43: =AS42+1 -> 54 | AT43: 11.53 | AU43: 0.75
A44: =A43+1 -> 55 | B44: 35.1 | C44: 10.6 | E44: =E43+1 -> 55 | F44: 77.7 | G44: 23.8 | I44: =I43+1 -> 55 | J44: 6.35 | K44: 1.45 | M44: =M43+1 -> 55 | N44: 4.55 | O44: 1.56 | Q44: =Q43+1 -> 55 | R44: 11 | S44: 1.16 | U44: =U43+1 -> 55 | V44: 9.07 | W44: 1.83 | Y44: =Y43+1 -> 55 | Z44: 8.97 | AA44: 1.9 | AC44: =AC43+1 -> 55 | AD44: 9.88 | AE44: 1.04 | AG44: =AG43+1 -> 55 | AH44: 9.16 | AI44: 1.67 | AK44: =AK43+1 -> 55 | AL44: 11.16 | AM44: 1.39 | AO44: =AO43+1 -> 55 | AP44: 11.91 | AQ44: 0.29 | AS44: =AS43+1 -> 55 | AT44: 11.53 | AU44: 0.75
A45: =A44+1 -> 56 | B45: 35.1 | C45: 10.6 | E45: =E44+1 -> 56 | F45: 77.7 | G45: 23.8 | I45: =I44+1 -> 56 | J45: 6.35 | K45: 1.45 | M45: =M44+1 -> 56 | N45: 4.55 | O45: 1.56 | Q45: =Q44+1 -> 56 | R45: 11 | S45: 1.16 | U45: =U44+1 -> 56 | V45: 8.91 | W45: 1.54 | Y45: =Y44+1 -> 56 | Z45: 8.83 | AA45: 1.63 | AC45: =AC44+1 -> 56 | AD45: 9.27 | AE45: 1.79 | AG45: =AG44+1 -> 56 | AH45: 8.23 | AI45: 1.83 | AK45: =AK44+1 -> 56 | AL45: 11.2 | AM45: 1.03 | AO45: =AO44+1 -> 56 | AP45: 11.7 | AQ45: 0.53 | AS45: =AS44+1 -> 56 | AT45: 11.45 | AU45: 0.72
A46: =A45+1 -> 57 | B46: 35.1 | C46: 10.6 | E46: =E45+1 -> 57 | F46: 77.7 | G46: 23.8 | I46: =I45+1 -> 57 | J46: 6.35 | K46: 1.45 | M46: =M45+1 -> 57 | N46: 4.55 | O46: 1.56 | Q46: =Q45+1 -> 57 | R46: 11 | S46: 1.16 | U46: =U45+1 -> 57 | V46: 8.91 | W46: 1.54 | Y46: =Y45+1 -> 57 | Z46: 8.83 | AA46: 1.63 | AC46: =AC45+1 -> 57 | AD46: 9.27 | AE46: 1.79 | AG46: =AG45+1 -> 57 | AH46: 8.23 | AI46: 1.83 | AK46: =AK45+1 -> 57 | AL46: 11.2 | AM46: 1.03 | AO46: =AO45+1 -> 57 | AP46: 11.7 | AQ46: 0.53 | AS46: =AS45+1 -> 57 | AT46: 11.45 | AU46: 0.72
A47: =A46+1 -> 58 | B47: 35.1 | C47: 10.6 | E47: =E46+1 -> 58 | F47: 77.7 | G47: 23.8 | I47: =I46+1 -> 58 | J47: 6.35 | K47: 1.45 | M47: =M46+1 -> 58 | N47: 4.55 | O47: 1.56 | Q47: =Q46+1 -> 58 | R47: 11 | S47: 1.16 | U47: =U46+1 -> 58 | V47: 8.91 | W47: 1.54 | Y47: =Y46+1 -> 58 | Z47: 8.83 | AA47: 1.63 | AC47: =AC46+1 -> 58 | AD47: 9.27 | AE47: 1.79 | AG47: =AG46+1 -> 58 | AH47: 8.23 | AI47: 1.83 | AK47: =AK46+1 -> 58 | AL47: 11.2 | AM47: 1.03 | AO47: =AO46+1 -> 58 | AP47: 11.7 | AQ47: 0.53 | AS47: =AS46+1 -> 58 | AT47: 11.45 | AU47: 0.72
... A89: =A88+1 -> 100 | B89: 60.7 | C89: 26 | E89: =E88+1 -> 100 | F89: 152.2 | G89: 83.1 | I89: =I88+1 -> 100 | J89: 5.69 | K89: 1.01 | M89: =M88+1 -> 100 | N89: 4.1 | O89: 1.05 | Q89: =Q88+1 -> 100 | R89: 11 | S89: 1.16 | U89: =U88+1 -> 100 | V89: 7.58 | W89: 0.74 | Y89: =Y88+1 -> 100 | Z89: 7.25 | AA89: 0.61 | AC89: =AC88+1 -> 100 | AD89: 6.8 | AE89: 1.09 | AG89: =AG88+1 -> 100 | AH89: 5.8 | AI89: 1.09 | AK89: =AK88+1 -> 100 | AL89: 10 | AM89: 1.22 | AO89: =AO88+1 -> 100 | AP89: 11 | AQ89: 1.73 | AS89: =AS88+1 -> 100 | AT89: 10.5 | AU89: 1.45

Sheet FLUENCIAS
A1: Fluencia Semantica MEDIA | F1: Fluencia Semantica DESVIO | K1: FLUENCIA FONOLOGICA MEDIA | P1: FLUENCIA FONOLOGICA DESVIO
A2: EDAD | B2: Primario | C2: Secundario | D2: Terciario | F2: EDAD | G2: Primario | H2: Secundario | I2: Terciario | K2: EDAD | L2: Primario | M2: Secundario | N2: Terciario | P2: EDAD | Q2: Primario | R2: Secundario | S2: Terciario
A3: 15 | B3: 16.5 | C3: 20.9 | D3: 23.8 | F3: 15 | G3: 2.8 | H3: 5.6 | I3: 6.2 | K3: 15 | L3: 12.8 | M3: 16.3 | N3: 18.1 | P3: 15 | Q3: 3.9 | R3: 6.1 | S3: 6.2
A4: 16 | B4: 16.5 | C4: 20.9 | D4: 23.8 | F4: 16 | G4: 2.8 | H4: 5.6 | I4: 6.2 | K4: 16 | L4: 12.8 | M4: 16.3 | N4: 18.1 | P4: 16 | Q4: 3.9 | R4: 6.1 | S4: 6.2
A5: 17 | B5: 16.5 | C5: 20.9 | D5: 23.8 | F5: 17 | G5: 2.8 | H5: 5.6 | I5: 6.2 | K5: 17 | L5: 12.8 | M5: 16.3 | N5: 18.1 | P5: 17 | Q5: 3.9 | R5: 6.1 | S5: 6.2
A6: 18 | B6: 16.5 | C6: 20.9 | D6: 23.8 | F6: 18 | G6: 2.8 | H6: 5.6 | I6: 6.2 | K6: 18 | L6: 12.8 | M6: 16.3 | N6: 18.1 | P6: 18 | Q6: 3.9 | R6: 6.1 | S6: 6.2
A7: 19 | B7: 16.5 | C7: 20.9 | D7: 23.8 | F7: 19 | G7: 2.8 | H7: 5.6 | I7: 6.2 | K7: 19 | L7: 12.8 | M7: 16.3 | N7: 18.1 | P7: 19 | Q7: 3.9 | R7: 6.1 | S7: 6.2
A8: 20 | B8: 16.5 | C8: 20.9 | D8: 23.8 | F8: 20 | G8: 2.8 | H8: 5.6 | I8: 6.2 | K8: 20 | L8: 12.8 | M8: 16.3 | N8: 18.1 | P8: 20 | Q8: 3.9 | R8: 6.1 | S8: 6.2
A9: 21 | B9: 16.5 | C9: 20.9 | D9: 23.8 | F9: 21 | G9: 2.8 | H9: 5.6 | I9: 6.2 | K9: 21 | L9: 12.8 | M9: 16.3 | N9: 18.1 | P9: 21 | Q9: 3.9 | R9: 6.1 | S9: 6.2
A10: 22 | B10: 16.5 | C10: 20.9 | D10: 23.8 | F10: 22 | G10: 2.8 | H10: 5.6 | I10: 6.2 | K10: 22 | L10: 12.8 | M10: 16.3 | N10: 18.1 | P10: 22 | Q10: 3.9 | R10: 6.1 | S10: 6.2
A11: 23 | B11: 16.5 | C11: 20.9 | D11: 23.8 | F11: 23 | G11: 2.8 | H11: 5.6 | I11: 6.2 | K11: 23 | L11: 12.8 | M11: 16.3 | N11: 18.1 | P11: 23 | Q11: 3.9 | R11: 6.1 | S11: 6.2
A12: 24 | B12: 16.5 | C12: 20.9 | D12: 23.8 | F12: 24 | G12: 2.8 | H12: 5.6 | I12: 6.2 | K12: 24 | L12: 12.8 | M12: 16.3 | N12: 18.1 | P12: 24 | Q12: 3.9 | R12: 6.1 | S12: 6.2
A13: 25 | B13: 16.5 | C13: 20.9 | D13: 23.8 | F13: 25 | G13: 2.8 | H13: 5.6 | I13: 6.2 | K13: 25 | L13: 12.8 | M13: 16.3 | N13: 18.1 | P13: 25 | Q13: 3.9 | R13: 6.1 | S13: 6.2
A14: 26 | B14: 16.5 | C14: 20.9 | D14: 23.8 | F14: 26 | G14: 2.8 | H14: 5.6 | I14: 6.2 | K14: 26 | L14: 12.8 | M14: 16.3 | N14: 18.1 | P14: 26 | Q14: 3.9 | R14: 6.1 | S14: 6.2
... A34: 46 | B34: 18.7 | C34: 22.4 | D34: 22.4 | F34: 46 | G34: 3 | H34: 4.7 | I34: 4.8 | K34: 46 | L34: 14.8 | M34: 19 | N34: 17.1 | P34: 46 | Q34: 2.6 | R34: 4.7 | S34: 4.1
A35: =A34+1 -> 47 | B35: 18.7 | C35: 22.4 | D35: 22.4 | F35: =F34+1 -> 47 | G35: 3 | H35: 4.7 | I35: 4.8 | K35: =K34+1 -> 47 | L35: 14.8 | M35: 19 | N35: 17.1 | P35: =P34+1 -> 47 | Q35: 2.6 | R35: 4.7 | S35: 4.1
A36: =A35+1 -> 48 | B36: 18.7 | C36: 22.4 | D36: 22.4 | F36: =F35+1 -> 48 | G36: 3 | H36: 4.7 | I36: 4.8 | K36: =K35+1 -> 48 | L36: 14.8 | M36: 19 | N36: 17.1 | P36: =P35+1 -> 48 | Q36: 2.6 | R36: 4.7 | S36: 4.1
A37: =A36+1 -> 49 | B37: 18.7 | C37: 22.4 | D37: 22.4 | F37: =F36+1 -> 49 | G37: 3 | H37: 4.7 | I37: 4.8 | K37: =K36+1 -> 49 | L37: 14.8 | M37: 19 | N37: 17.1 | P37: =P36+1 -> 49 | Q37: 2.6 | R37: 4.7 | S37: 4.1
A38: =A37+1 -> 50 | B38: 18.7 | C38: 22.4 | D38: 22.4 | F38: =F37+1 -> 50 | G38: 3 | H38: 4.7 | I38: 4.8 | K38: =K37+1 -> 50 | L38: 14.8 | M38: 19 | N38: 17.1 | P38: =P37+1 -> 50 | Q38: 2.6 | R38: 4.7 | S38: 4.1
A39: =A38+1 -> 51 | B39: 18.7 | C39: 22.4 | D39: 22.4 | F39: =F38+1 -> 51 | G39: 3 | H39: 4.7 | I39: 4.8 | K39: =K38+1 -> 51 | L39: 14.8 | M39: 19 | N39: 17.1 | P39: =P38+1 -> 51 | Q39: 2.6 | R39: 4.7 | S39: 4.1
A40: =A39+1 -> 52 | B40: 18.7 | C40: 22.4 | D40: 22.4 | F40: =F39+1 -> 52 | G40: 3 | H40: 4.7 | I40: 4.8 | K40: =K39+1 -> 52 | L40: 14.8 | M40: 19 | N40: 17.1 | P40: =P39+1 -> 52 | Q40: 2.6 | R40: 4.7 | S40: 4.1
A41: =A40+1 -> 53 | B41: 18.7 | C41: 22.4 | D41: 22.4 | F41: =F40+1 -> 53 | G41: 3 | H41: 4.7 | I41: 4.8 | K41: =K40+1 -> 53 | L41: 14.8 | M41: 19 | N41: 17.1 | P41: =P40+1 -> 53 | Q41: 2.6 | R41: 4.7 | S41: 4.1
A42: =A41+1 -> 54 | B42: 18.7 | C42: 22.4 | D42: 22.4 | F42: =F41+1 -> 54 | G42: 3 | H42: 4.7 | I42: 4.8 | K42: =K41+1 -> 54 | L42: 14.8 | M42: 19 | N42: 17.1 | P42: =P41+1 -> 54 | Q42: 2.6 | R42: 4.7 | S42: 4.1
A43: =A42+1 -> 55 | B43: 18.7 | C43: 22.4 | D43: 22.4 | F43: =F42+1 -> 55 | G43: 3 | H43: 4.7 | I43: 4.8 | K43: =K42+1 -> 55 | L43: 14.8 | M43: 19 | N43: 17.1 | P43: =P42+1 -> 55 | Q43: 2.6 | R43: 4.7 | S43: 4.1
A44: =A43+1 -> 56 | B44: 15.5 | C44: 19.2 | D44: 21.6 | F44: =F43+1 -> 56 | G44: 3.7 | H44: 5.2 | I44: 5.4 | K44: =K43+1 -> 56 | L44: 13.3 | M44: 15.2 | N44: 16.6 | P44: =P43+1 -> 56 | Q44: 5.7 | R44: 4 | S44: 3.2
A45: =A44+1 -> 57 | B45: 15.5 | C45: 19.2 | D45: 21.6 | F45: =F44+1 -> 57 | G45: 3.7 | H45: 5.2 | I45: 5.4 | K45: =K44+1 -> 57 | L45: 13.3 | M45: 15.2 | N45: 16.6 | P45: =P44+1 -> 57 | Q45: 5.7 | R45: 4 | S45: 3.2
A46: =A45+1 -> 58 | B46: 15.5 | C46: 19.2 | D46: 21.6 | F46: =F45+1 -> 58 | G46: 3.7 | H46: 5.2 | I46: 5.4 | K46: =K45+1 -> 58 | L46: 13.3 | M46: 15.2 | N46: 16.6 | P46: =P45+1 -> 58 | Q46: 5.7 | R46: 4 | S46: 3.2
... A88: =A87+1 -> 100 | B88: 12.4 | C88: 16.5 | D88: 15.1 | F88: =F87+1 -> 100 | G88: 2.9 | H88: 2.3 | I88: 3.5 | K88: =K87+1 -> 100 | L88: 9.8 | M88: 14 | N88: 9.8 | P88: =P87+1 -> 100 | Q88: 4.7 | R88: 3.7 | S88: 4.7

Sheet BACK UP
B2: Datos Personales
B3: Nombre
B4: Edad | C4: 82
B5: Nivel Educativo Alcanzado | C5: Terciario
C7: Prueba | D7: PB | E7: Z | G7: Media | H7: Desvio
B8: Atención y Funciones Ejecutivas | C8: DD | E8: =(D8-G8)/H8 -> -4.6746032 | G8: =VLOOKUP(C4,PRUEBAS!$I$3:$K$89,2,FALSE) -> 5.89 | H8: =VLOOKUP(C4,PRUEBAS!$I$3:$K$89,3,FALSE) -> 1.26
C9: DI | E9: =(D9-G9)/H9 -> -4.1262136 | G9: =VLOOKUP(C4,PRUEBAS!$M$3:$O$89,2,FALSE) -> 4.25 | H9: =VLOOKUP(C4,PRUEBAS!$M$3:$O$89,3,FALSE) -> 1.03
C10: TMT A | E10: =(D10-G10)/H10 -> -2.3346154 | G10: =VLOOKUP(C4,PRUEBAS!$A$3:$C$89,2,FALSE) -> 60.7 | H10: =VLOOKUP(C4,PRUEBAS!$A$3:$C$89,3,FALSE) -> 26
C11: TMT B | E11: =(D11-G11)/H11 -> -1.8315283 | G11: =VLOOKUP(C4,PRUEBAS!$E$3:$G$89,2,FALSE) -> 152.2 | H11: =VLOOKUP(C4,PRUEBAS!$E$3:$G$89,3,FALSE) -> 83.1
C12: FF | E12: =(D12-G12)/H12 -> -2.0851064 | G12: =VLOOKUP(C4,FLUENCIAS!$K$2:$N$88,(MATCH(C5,FLUENCIAS!$L$2:$N$2,0))+1,0) -> 9.8 | H12: =VLOOKUP(C4,FLUENCIAS!$P$2:$S$88,(MATCH(C5,FLUENCIAS!$Q$2:$S$2,0))+1,0) -> 4.7
B13: Memoria episódica | C13: BEM – MS AST | E13: =(D13-G13)/H13 -> -4.8271605 | G13: =VLOOKUP(C4,PRUEBAS!$AC$3:$AE$89,2,FALSE) -> 7.82 | H13: =VLOOKUP(C4,PRUEBAS!$AC$3:$AE$89,3,FALSE) -> 1.62
C14: BEM – MS RSE | E14: =(D14-G14)/H14 -> -4.7310345 | G14: =VLOOKUP(C4,PRUEBAS!$AG$3:$AI$89,2,FALSE) -> 6.86 | H14: =VLOOKUP(C4,PRUEBAS!$AG$3:$AI$89,3,FALSE) -> 1.45
C15: BEM – MS Sem | E15: =(D15-G15)/H15 -> -5.5865922 | G15: =VLOOKUP(C4,PRUEBAS!$AK$3:$AM$89,2,FALSE) -> 10 | H15: =VLOOKUP(C4,PRUEBAS!$AK$3:$AM$89,3,FALSE) -> 1.79
C16: BEM – MS Rec | E16: =(D16-G16)/H16 -> -14.111111 | G16: =VLOOKUP(C4,PRUEBAS!$AO$3:$AQ$89,2,FALSE) -> 11.43 | H16: =VLOOKUP(C4,PRUEBAS!$AO$3:$AQ$89,3,FALSE) -> 0.81
C17: BEM – MS CE | E17: =(D17-G17)/H17 -> -5.2777778 | G17: =VLOOKUP(C4,PRUEBAS!$AS$3:$AU$89,2,FALSE) -> 10.45 | H17: =VLOOKUP(C4,PRUEBAS!$AS$3:$AU$89,3,FALSE) -> 1.98
C18: BEM – ML Inm | E18: =(D18-G18)/H18 -> -6.0381679 | G18: =VLOOKUP(C4,PRUEBAS!$U$3:$W$89,2,FALSE) -> 7.91 | H18: =VLOOKUP(C4,PRUEBAS!$U$3:$W$89,3,FALSE) -> 1.31
C19: BEM – ML Dif | E19: =(D19-G19)/H19 -> -6.3114754 | G19: =VLOOKUP(C4,PRUEBAS!$Y$3:$AA$89,2,FALSE) -> 7.7 | H19: =VLOOKUP(C4,PRUEBAS!$Y$3:$AA$89,3,FALSE) -> 1.22
B20: Lenguaje | C20: FF | E20: =(D20-G20)/H20 -> -2.0851064 | G20: =VLOOKUP(C4,FLUENCIAS!$K$2:$N$88,(MATCH(C5,FLUENCIAS!$L$2:$N$2,0))+1,0) -> 9.8 | H20: =VLOOKUP(C4,FLUENCIAS!$P$2:$S$88,(MATCH(C5,FLUENCIAS!$Q$2:$S$2,0))+1,0) -> 4.7
C21: FS | E21: =(D21-G21)/H21 -> -4.3142857 | G21: =VLOOKUP(C4,FLUENCIAS!$A$2:$D$88,(MATCH(C5,FLUENCIAS!$B$2:$D$2,0))+1,0) -> 15.1 | H21: =VLOOKUP(C4,FLUENCIAS!$F$2:$I$88,(MATCH(C5,FLUENCIAS!$G$2:$I$2,0))+1,0) -> 3.5
C22: TBA | E22: =(D22-G22)/H22 -> -9.4827586 | G22: =VLOOKUP(C4,PRUEBAS!$Q$3:$S$89,2,FALSE) -> 11 | H22: =VLOOKUP(C4,PRUEBAS!$Q$3:$S$89,3,FALSE) -> 1.16
